{
 "cells": [
  {
   "cell_type": "code",
   "execution_count": null,
   "id": "cad85499",
   "metadata": {},
   "outputs": [
    {
     "name": "stderr",
     "output_type": "stream",
     "text": [
      "\u001b[0;31m[<class 'saspy.sasexceptions.SASIOConnectionError'>, SASIOConnectionError('No SAS process attached. SAS process has terminated unexpectedly.'), <traceback object at 0x7fa324154640>]\n",
      "\u001b[0m"
     ]
    },
    {
     "name": "stdout",
     "output_type": "stream",
     "text": [
      "SAS Connection failed. No connection established. Double check your settings in sascfg_personal.py file.\n",
      "Attempted to run program /opt/sasinside/SASHome/SASFoundation/9.4/bin/sas_u8 with the following parameters:['/opt/sasinside/SASHome/SASFoundation/9.4/bin/sas_u8', '-nodms', '-stdio', '-terminal', '-nosyntaxcheck', '-pagesize', 'MAX', '']\n",
      "Try running the following command (where saspy is running) manually to see if you can get more information on what went wrong:\n",
      "/opt/sasinside/SASHome/SASFoundation/9.4/bin/sas_u8 -nodms -stdio -terminal -nosyntaxcheck -pagesize MAX  \n",
      "\n",
      "No SAS process attached. SAS process has terminated unexpectedly.\n",
      "Invalid response from SAS on inital submission. printing the SASLOG as diagnostic\n",
      "\n"
     ]
    }
   ],
   "source": [
    "filename x \"./data_GBIF_Dfrontalis.csv\";\n",
    "proc import datafile=x out=_csv dbms=csv replace; run;"
   ]
  },
  {
   "cell_type": "code",
   "execution_count": null,
   "id": "d6e42e63",
   "metadata": {},
   "outputs": [
    {
     "name": "stderr",
     "output_type": "stream",
     "text": [
      "\u001b[0;31m[<class 'saspy.sasexceptions.SASIOConnectionError'>, SASIOConnectionError('No SAS process attached. SAS process has terminated unexpectedly.'), <traceback object at 0x7fa324127f00>]\n",
      "\u001b[0m"
     ]
    },
    {
     "name": "stdout",
     "output_type": "stream",
     "text": [
      "SAS Connection failed. No connection established. Double check your settings in sascfg_personal.py file.\n",
      "Attempted to run program /opt/sasinside/SASHome/SASFoundation/9.4/bin/sas_u8 with the following parameters:['/opt/sasinside/SASHome/SASFoundation/9.4/bin/sas_u8', '-nodms', '-stdio', '-terminal', '-nosyntaxcheck', '-pagesize', 'MAX', '']\n",
      "Try running the following command (where saspy is running) manually to see if you can get more information on what went wrong:\n",
      "/opt/sasinside/SASHome/SASFoundation/9.4/bin/sas_u8 -nodms -stdio -terminal -nosyntaxcheck -pagesize MAX  \n",
      "\n",
      "No SAS process attached. SAS process has terminated unexpectedly.\n",
      "Invalid response from SAS on inital submission. printing the SASLOG as diagnostic\n",
      "\n"
     ]
    }
   ],
   "source": [
    "/opt/sasinside/SASHome/SASFoundation/9.4/bin/sas_u8 -nodms -stdio -terminal -nosyntaxcheck -pagesize MAX"
   ]
  },
  {
   "cell_type": "code",
   "execution_count": null,
   "id": "d554d85c",
   "metadata": {},
   "outputs": [],
   "source": []
  }
 ],
 "metadata": {
  "kernelspec": {
   "display_name": "SAS",
   "language": "sas",
   "name": "sas"
  },
  "language_info": {
   "codemirror_mode": "sas",
   "file_extension": ".sas",
   "mimetype": "text/x-sas",
   "name": "sas"
  }
 },
 "nbformat": 4,
 "nbformat_minor": 5
}
